<?xml version="1.0"?>
<robot xmlns:xacro="http://www.ros.org/wiki/xacro" name="humanoid">

  <!-- Include materials -->
  <xacro:include filename="$(find humanoid_description)/urdf/materials.xacro" />

  <!-- Include Gazebo plugins -->
  <xacro:include filename="$(find humanoid_description)/urdf/gazebo.xacro" />

  <!-- Base link -->
  <link name="base_link">
    <visual>
      <geometry>
        <box size="0.3 0.2 0.1"/>
      </geometry>
      <material name="blue"/>
    </visual>
    <collision>
      <geometry>
        <box size="0.3 0.2 0.1"/>
      </geometry>
    </collision>
    <inertial>
      <mass value="5.0"/>
      <inertia ixx="0.1" ixy="0.0" ixz="0.0" iyy="0.1" iyz="0.0" izz="0.1"/>
    </inertial>
  </link>

  <!-- Torso -->
  <joint name="torso_joint" type="fixed">
    <parent link="base_link"/>
    <child link="torso"/>
    <origin xyz="0 0 0.15" rpy="0 0 0"/>
  </joint>

  <link name="torso">
    <visual>
      <geometry>
        <box size="0.25 0.15 0.4"/>
      </geometry>
      <material name="white"/>
    </visual>
    <collision>
      <geometry>
        <box size="0.25 0.15 0.4"/>
      </geometry>
    </collision>
    <inertial>
      <mass value="3.0"/>
      <inertia ixx="0.05" ixy="0.0" ixz="0.0" iyy="0.05" iyz="0.0" izz="0.05"/>
    </inertial>
  </link>

  <!-- Head -->
  <joint name="head_joint" type="fixed">
    <parent link="torso"/>
    <child link="head"/>
    <origin xyz="0 0 0.25" rpy="0 0 0"/>
  </joint>

  <link name="head">
    <visual>
      <geometry>
        <sphere radius="0.1"/>
      </geometry>
      <material name="white"/>
    </visual>
    <collision>
      <geometry>
        <sphere radius="0.1"/>
      </geometry>
    </collision>
    <inertial>
      <mass value="1.0"/>
      <inertia ixx="0.002" ixy="0.0" ixz="0.0" iyy="0.002" iyz="0.0" izz="0.002"/>
    </inertial>
  </link>

  <!-- Left Arm -->
  <joint name="left_shoulder_joint" type="revolute">
    <parent link="torso"/>
    <child link="left_upper_arm"/>
    <origin xyz="0.15 0 0.1" rpy="0 0 0"/>
    <axis xyz="0 1 0"/>
    <limit lower="-1.57" upper="1.57" effort="100" velocity="1"/>
  </joint>

  <link name="left_upper_arm">
    <visual>
      <geometry>
        <cylinder length="0.3" radius="0.05"/>
      </geometry>
      <material name="red"/>
      <origin xyz="0 0 -0.15" rpy="1.57 0 0"/>
    </visual>
    <collision>
      <geometry>
        <cylinder length="0.3" radius="0.05"/>
      </geometry>
      <origin xyz="0 0 -0.15" rpy="1.57 0 0"/>
    </collision>
    <inertial>
      <mass value="0.8"/>
      <inertia ixx="0.005" ixy="0.0" ixz="0.0" iyy="0.005" iyz="0.0" izz="0.005"/>
    </inertial>
  </link>

  <joint name="left_elbow_joint" type="revolute">
    <parent link="left_upper_arm"/>
    <child link="left_lower_arm"/>
    <origin xyz="0 0 -0.3" rpy="0 0 0"/>
    <axis xyz="0 1 0"/>
    <limit lower="-1.57" upper="1.57" effort="100" velocity="1"/>
  </joint>

  <link name="left_lower_arm">
    <visual>
      <geometry>
        <cylinder length="0.25" radius="0.04"/>
      </geometry>
      <material name="red"/>
      <origin xyz="0 0 -0.125" rpy="1.57 0 0"/>
    </visual>
    <collision>
      <geometry>
        <cylinder length="0.25" radius="0.04"/>
      </geometry>
      <origin xyz="0 0 -0.125" rpy="1.57 0 0"/>
    </collision>
    <inertial>
      <mass value="0.5"/>
      <inertia ixx="0.003" ixy="0.0" ixz="0.0" iyy="0.003" iyz="0.0" izz="0.003"/>
    </inertial>
  </link>

  <!-- Right Arm -->
  <joint name="right_shoulder_joint" type="revolute">
    <parent link="torso"/>
    <child link="right_upper_arm"/>
    <origin xyz="-0.15 0 0.1" rpy="0 0 0"/>
    <axis xyz="0 1 0"/>
    <limit lower="-1.57" upper="1.57" effort="100" velocity="1"/>
  </joint>

  <link name="right_upper_arm">
    <visual>
      <geometry>
        <cylinder length="0.3" radius="0.05"/>
      </geometry>
      <material name="red"/>
      <origin xyz="0 0 -0.15" rpy="1.57 0 0"/>
    </visual>
    <collision>
      <geometry>
        <cylinder length="0.3" radius="0.05"/>
      </geometry>
      <origin xyz="0 0 -0.15" rpy="1.57 0 0"/>
    </collision>
    <inertial>
      <mass value="0.8"/>
      <inertia ixx="0.005" ixy="0.0" ixz="0.0" iyy="0.005" iyz="0.0" izz="0.005"/>
    </inertial>
  </link>

  <joint name="right_elbow_joint" type="revolute">
    <parent link="right_upper_arm"/>
    <child link="right_lower_arm"/>
    <origin xyz="0 0 -0.3" rpy="0 0 0"/>
    <axis xyz="0 1 0"/>
    <limit lower="-1.57" upper="1.57" effort="100" velocity="1"/>
  </joint>

  <link name="right_lower_arm">
    <visual>
      <geometry>
        <cylinder length="0.25" radius="0.04"/>
      </geometry>
      <material name="red"/>
      <origin xyz="0 0 -0.125" rpy="1.57 0 0"/>
    </visual>
    <collision>
      <geometry>
        <cylinder length="0.25" radius="0.04"/>
      </geometry>
      <origin xyz="0 0 -0.125" rpy="1.57 0 0"/>
    </collision>
    <inertial>
      <mass value="0.5"/>
      <inertia ixx="0.003" ixy="0.0" ixz="0.0" iyy="0.003" iyz="0.0" izz="0.003"/>
    </inertial>
  </link>

  <!-- Left Leg -->
  <joint name="left_hip_joint" type="revolute">
    <parent link="base_link"/>
    <child link="left_upper_leg"/>
    <origin xyz="0.05 0 -0.05" rpy="0 0 0"/>
    <axis xyz="0 1 0"/>
    <limit lower="-1.57" upper="1.57" effort="100" velocity="1"/>
  </joint>

  <link name="left_upper_leg">
    <visual>
      <geometry>
        <cylinder length="0.4" radius="0.06"/>
      </geometry>
      <material name="green"/>
      <origin xyz="0 0 -0.2" rpy="1.57 0 0"/>
    </visual>
    <collision>
      <geometry>
        <cylinder length="0.4" radius="0.06"/>
      </geometry>
      <origin xyz="0 0 -0.2" rpy="1.57 0 0"/>
    </collision>
    <inertial>
      <mass value="1.0"/>
      <inertia ixx="0.01" ixy="0.0" ixz="0.0" iyy="0.01" iyz="0.0" izz="0.01"/>
    </inertial>
  </link>

  <joint name="left_knee_joint" type="revolute">
    <parent link="left_upper_leg"/>
    <child link="left_lower_leg"/>
    <origin xyz="0 0 -0.4" rpy="0 0 0"/>
    <axis xyz="0 1 0"/>
    <limit lower="-1.57" upper="1.57" effort="100" velocity="1"/>
  </joint>

  <link name="left_lower_leg">
    <visual>
      <geometry>
        <cylinder length="0.35" radius="0.05"/>
      </geometry>
      <material name="green"/>
      <origin xyz="0 0 -0.175" rpy="1.57 0 0"/>
    </visual>
    <collision>
      <geometry>
        <cylinder length="0.35" radius="0.05"/>
      </geometry>
      <origin xyz="0 0 -0.175" rpy="1.57 0 0"/>
    </collision>
    <inertial>
      <mass value="0.8"/>
      <inertia ixx="0.008" ixy="0.0" ixz="0.0" iyy="0.008" iyz="0.0" izz="0.008"/>
    </inertial>
  </link>

  <!-- Right Leg -->
  <joint name="right_hip_joint" type="revolute">
    <parent link="base_link"/>
    <child link="right_upper_leg"/>
    <origin xyz="-0.05 0 -0.05" rpy="0 0 0"/>
    <axis xyz="0 1 0"/>
    <limit lower="-1.57" upper="1.57" effort="100" velocity="1"/>
  </joint>

  <link name="right_upper_leg">
    <visual>
      <geometry>
        <cylinder length="0.4" radius="0.06"/>
      </geometry>
      <material name="green"/>
      <origin xyz="0 0 -0.2" rpy="1.57 0 0"/>
    </visual>
    <collision>
      <geometry>
        <cylinder length="0.4" radius="0.06"/>
      </geometry>
      <origin xyz="0 0 -0.2" rpy="1.57 0 0"/>
    </collision>
    <inertial>
      <mass value="1.0"/>
      <inertia ixx="0.01" ixy="0.0" ixz="0.0" iyy="0.01" iyz="0.0" izz="0.01"/>
    </inertial>
  </link>

  <joint name="right_knee_joint" type="revolute">
    <parent link="right_upper_leg"/>
    <child link="right_lower_leg"/>
    <origin xyz="0 0 -0.4" rpy="0 0 0"/>
    <axis xyz="0 1 0"/>
    <limit lower="-1.57" upper="1.57" effort="100" velocity="1"/>
  </joint>

  <link name="right_lower_leg">
    <visual>
      <geometry>
        <cylinder length="0.35" radius="0.05"/>
      </geometry>
      <material name="green"/>
      <origin xyz="0 0 -0.175" rpy="1.57 0 0"/>
    </visual>
    <collision>
      <geometry>
        <cylinder length="0.35" radius="0.05"/>
      </geometry>
      <origin xyz="0 0 -0.175" rpy="1.57 0 0"/>
    </collision>
    <inertial>
      <mass value="0.8"/>
      <inertia ixx="0.008" ixy="0.0" ixz="0.0" iyy="0.008" iyz="0.0" izz="0.008"/>
    </inertial>
  </link>

</robot>